Workbook

Sheet Productos
A1: Referencia | B1: Producto | C1: Categoría | D1: Subcategoría | E1: Marca | F1: Colores | G1: Unidades | H1: Costo proveedor (COP) | I1: Margen | J1: Precio sin redondear | K1: Precio de venta (COP) | L1: Ganancia por unidad | M1: Margen real | N1: Foto | O1: Imagen | P1: Archivo de imagen
A2: CON-NSW2 | B2: Nintendo Switch 2 | C2: TV y consolas | D2: Consolas | E2: Nintendo | F2: Negro | G2: Sin control | H2: 1900000 | I2: =INDEX(Márgenes!$C$7:$C$23,MATCH(D2,Márgenes!$B$7:$B$23,0)) | J2: =MAX(H2*(1+I2),H2+Márgenes!$B$4) | K2: =IF(J2<1000000,CEILING(J2,1000),CEILING(J2,10000))-100 | L2: =K2-H2 | M2: =IF(K2=0,0,L2/K2) | O2: Lista | P2: imagenes/CON-NSW2.jpg
A3: CON-PS5SLIM-1TB | B3: Sony PlayStation 5 Slim Edición Disco Físico 1TB | C3: TV y consolas | D3: Consolas | E3: Sony | G3: Sin control | H3: 2800000 | I3: =INDEX(Márgenes!$C$7:$C$23,MATCH(D3,Márgenes!$B$7:$B$23,0)) | J3: =MAX(H3*(1+I3),H3+Márgenes!$B$4) | K3: =IF(J3<1000000,CEILING(J3,1000),CEILING(J3,10000))-100 | L3: =K3-H3 | M3: =IF(K3=0,0,L3/K3) | O3: Lista | P3: imagenes/CON-PS5SLIM-1TB.jpg
A4: TAB-ACER-A10 | B4: Acer Iconia A10 10" 4GB+64GB | C4: Celulares y tablets | D4: Tablets | E4: Acer | F4: Negro | G4: Sin control | H4: 325000 | I4: =INDEX(Márgenes!$C$7:$C$23,MATCH(D4,Márgenes!$B$7:$B$23,0)) | J4: =MAX(H4*(1+I4),H4+Márgenes!$B$4) | K4: =IF(J4<1000000,CEILING(J4,1000),CEILING(J4,10000))-100 | L4: =K4-H4 | M4: =IF(K4=0,0,L4/K4) | O4: Lista | P4: imagenes/TAB-ACER-A10.jpg
A5: ZTE-A56PRO-4-128 | B5: ZTE A56 Pro 4GB+128GB | C5: Celulares y tablets | D5: Celulares | E5: ZTE | F5: Dorado/Amarillo, Blanco | G5: Sin control | H5: 345000 | I5: =INDEX(Márgenes!$C$7:$C$23,MATCH(D5,Márgenes!$B$7:$B$23,0)) | J5: =MAX(H5*(1+I5),H5+Márgenes!$B$4) | K5: =IF(J5<1000000,CEILING(J5,1000),CEILING(J5,10000))-100 | L5: =K5-H5 | M5: =IF(K5=0,0,L5/K5) | O5: Lista | P5: imagenes/ZTE-A56PRO-4-128.jpg
A6: ZTE-A35E-2-64 | B6: ZTE A35E 2GB+64GB | C6: Celulares y tablets | D6: Celulares | E6: ZTE | F6: Verde, Blanco | G6: Sin control | H6: 270000 | I6: =INDEX(Márgenes!$C$7:$C$23,MATCH(D6,Márgenes!$B$7:$B$23,0)) | J6: =MAX(H6*(1+I6),H6+Márgenes!$B$4) | K6: =IF(J6<1000000,CEILING(J6,1000),CEILING(J6,10000))-100 | L6: =K6-H6 | M6: =IF(K6=0,0,L6/K6) | O6: Lista | P6: imagenes/ZTE-A35E-2-64.jpg
A7: ZTE-V80MAX-4-256 | B7: ZTE Nubia V80 Max 4GB+256GB | C7: Celulares y tablets | D7: Celulares | E7: ZTE | F7: Negro | G7: Sin control | H7: 465000 | I7: =INDEX(Márgenes!$C$7:$C$23,MATCH(D7,Márgenes!$B$7:$B$23,0)) | J7: =MAX(H7*(1+I7),H7+Márgenes!$B$4) | K7: =IF(J7<1000000,CEILING(J7,1000),CEILING(J7,10000))-100 | L7: =K7-H7 | M7: =IF(K7=0,0,L7/K7) | O7: Lista | P7: imagenes/ZTE-V80MAX-4-256.jpg
A8: ZTE-A75-4-256 | B8: ZTE Blade A75 4GB+256GB | C8: Celulares y tablets | D8: Celulares | E8: ZTE | F8: Negro | G8: Sin control | H8: 395000 | I8: =INDEX(Márgenes!$C$7:$C$23,MATCH(D8,Márgenes!$B$7:$B$23,0)) | J8: =MAX(H8*(1+I8),H8+Márgenes!$B$4) | K8: =IF(J8<1000000,CEILING(J8,1000),CEILING(J8,10000))-100 | L8: =K8-H8 | M8: =IF(K8=0,0,L8/K8) | O8: Lista | P8: imagenes/ZTE-A75-4-256.jpg
A9: HON-X5CPLUS-4-256 | B9: Honor X5C Plus 4GB+256GB | C9: Celulares y tablets | D9: Celulares | E9: Honor | F9: Blanco | G9: Sin control | H9: 420000 | I9: =INDEX(Márgenes!$C$7:$C$23,MATCH(D9,Márgenes!$B$7:$B$23,0)) | J9: =MAX(H9*(1+I9),H9+Márgenes!$B$4) | K9: =IF(J9<1000000,CEILING(J9,1000),CEILING(J9,10000))-100 | L9: =K9-H9 | M9: =IF(K9=0,0,L9/K9) | O9: Lista | P9: imagenes/HON-X5CPLUS-4-256.jpg
A10: HON-T10-4-64 | B10: Honor Choice T10 4GB+64GB | C10: Celulares y tablets | D10: Tablets | E10: Honor | F10: Blanco | G10: Sin control | H10: 280000 | I10: =INDEX(Márgenes!$C$7:$C$23,MATCH(D10,Márgenes!$B$7:$B$23,0)) | J10: =MAX(H10*(1+I10),H10+Márgenes!$B$4) | K10: =IF(J10<1000000,CEILING(J10,1000),CEILING(J10,10000))-100 | L10: =K10-H10 | M10: =IF(K10=0,0,L10/K10) | O10: Lista | P10: imagenes/HON-T10-4-64.jpg
A11: HON-PLAY10-3-64 | B11: Honor Play 10 3GB+64GB | C11: Celulares y tablets | D11: Celulares | E11: Honor | F11: Negro, Azul | G11: Sin control | H11: 320000 | I11: =INDEX(Márgenes!$C$7:$C$23,MATCH(D11,Márgenes!$B$7:$B$23,0)) | J11: =MAX(H11*(1+I11),H11+Márgenes!$B$4) | K11: =IF(J11<1000000,CEILING(J11,1000),CEILING(J11,10000))-100 | L11: =K11-H11 | M11: =IF(K11=0,0,L11/K11) | O11: Lista | P11: imagenes/HON-PLAY10-3-64.jpg
A12: HON-400SMART-6-256 | B12: Honor 400 Smart 6GB+256GB | C12: Celulares y tablets | D12: Celulares | E12: Honor | F12: Dorado/Amarillo, Blanco | G12: Sin control | H12: 640000 | I12: =INDEX(Márgenes!$C$7:$C$23,MATCH(D12,Márgenes!$B$7:$B$23,0)) | J12: =MAX(H12*(1+I12),H12+Márgenes!$B$4) | K12: =IF(J12<1000000,CEILING(J12,1000),CEILING(J12,10000))-100 | L12: =K12-H12 | M12: =IF(K12=0,0,L12/K12) | O12: Lista | P12: imagenes/HON-400SMART-6-256.jpg
A13: INF-SMART20-4-64 | B13: Infinix Smart 20 4GB+64GB | C13: Celulares y tablets | D13: Celulares | E13: Infinix | F13: Naranja | G13: Sin control | H13: 395000 | I13: =INDEX(Márgenes!$C$7:$C$23,MATCH(D13,Márgenes!$B$7:$B$23,0)) | J13: =MAX(H13*(1+I13),H13+Márgenes!$B$4) | K13: =IF(J13<1000000,CEILING(J13,1000),CEILING(J13,10000))-100 | L13: =K13-H13 | M13: =IF(K13=0,0,L13/K13) | O13: Lista | P13: imagenes/INF-SMART20-4-64.jpg
A14: INF-SMART20-4-128 | B14: Infinix Smart 20 4GB+128GB | C14: Celulares y tablets | D14: Celulares | E14: Infinix | F14: Naranja | G14: Sin control | H14: 430000 | I14: =INDEX(Márgenes!$C$7:$C$23,MATCH(D14,Márgenes!$B$7:$B$23,0)) | J14: =MAX(H14*(1+I14),H14+Márgenes!$B$4) | K14: =IF(J14<1000000,CEILING(J14,1000),CEILING(J14,10000))-100 | L14: =K14-H14 | M14: =IF(K14=0,0,L14/K14) | O14: Lista | P14: imagenes/INF-SMART20-4-128.jpg
A15: INF-HOT70-4-128 | B15: Infinix Hot 70 4GB+128GB | C15: Celulares y tablets | D15: Celulares | E15: Infinix | F15: Azul | G15: Sin control | H15: 519900 | I15: =INDEX(Márgenes!$C$7:$C$23,MATCH(D15,Márgenes!$B$7:$B$23,0)) | J15: =MAX(H15*(1+I15),H15+Márgenes!$B$4) | K15: =IF(J15<1000000,CEILING(J15,1000),CEILING(J15,10000))-100 | L15: =K15-H15 | M15: =IF(K15=0,0,L15/K15) | O15: Lista | P15: imagenes/INF-HOT70-4-128.jpg
A16: TEC-SPARKGO3-4-128 | B16: Tecno Spark Go 3 4GB+128GB | C16: Celulares y tablets | D16: Celulares | E16: Tecno | G16: Sin control | H16: 380000 | I16: =INDEX(Márgenes!$C$7:$C$23,MATCH(D16,Márgenes!$B$7:$B$23,0)) | J16: =MAX(H16*(1+I16),H16+Márgenes!$B$4) | K16: =IF(J16<1000000,CEILING(J16,1000),CEILING(J16,10000))-100 | L16: =K16-H16 | M16: =IF(K16=0,0,L16/K16) | O16: Lista | P16: imagenes/TEC-SPARKGO3-4-128.jpg
A17: MOT-G06-4-128 | B17: Motorola Moto G06 4GB+128GB | C17: Celulares y tablets | D17: Celulares | E17: Motorola | F17: Azul | G17: Sin control | H17: 375000 | I17: =INDEX(Márgenes!$C$7:$C$23,MATCH(D17,Márgenes!$B$7:$B$23,0)) | J17: =MAX(H17*(1+I17),H17+Márgenes!$B$4) | K17: =IF(J17<1000000,CEILING(J17,1000),CEILING(J17,10000))-100 | L17: =K17-H17 | M17: =IF(K17=0,0,L17/K17) | O17: Lista | P17: imagenes/MOT-G06-4-128.jpg
A18: MOT-G17-4-128 | B18: Motorola Moto G17 4GB+128GB | C18: Celulares y tablets | D18: Celulares | E18: Motorola | F18: Morado | G18: Sin control | H18: 440000 | I18: =INDEX(Márgenes!$C$7:$C$23,MATCH(D18,Márgenes!$B$7:$B$23,0)) | J18: =MAX(H18*(1+I18),H18+Márgenes!$B$4) | K18: =IF(J18<1000000,CEILING(J18,1000),CEILING(J18,10000))-100 | L18: =K18-H18 | M18: =IF(K18=0,0,L18/K18) | O18: Lista | P18: imagenes/MOT-G17-4-128.jpg
A19: MOT-EDGE60F-8-256 | B19: Motorola Edge 60 Fusion 5G 8GB+256GB | C19: Celulares y tablets | D19: Celulares | E19: Motorola | G19: Sin control | H19: 900000 | I19: =INDEX(Márgenes!$C$7:$C$23,MATCH(D19,Márgenes!$B$7:$B$23,0)) | J19: =MAX(H19*(1+I19),H19+Márgenes!$B$4) | K19: =IF(J19<1000000,CEILING(J19,1000),CEILING(J19,10000))-100 | L19: =K19-H19 | M19: =IF(K19=0,0,L19/K19) | O19: Lista | P19: imagenes/MOT-EDGE60F-8-256.jpg
A20: MOT-EDGE70F-12-256 | B20: Motorola Edge 70 Fusion 5G 12GB+256GB | C20: Celulares y tablets | D20: Celulares | E20: Motorola | F20: Verde, Azul | G20: Sin control | H20: 1280000 | I20: =INDEX(Márgenes!$C$7:$C$23,MATCH(D20,Márgenes!$B$7:$B$23,0)) | J20: =MAX(H20*(1+I20),H20+Márgenes!$B$4) | K20: =IF(J20<1000000,CEILING(J20,1000),CEILING(J20,10000))-100 | L20: =K20-H20 | M20: =IF(K20=0,0,L20/K20) | O20: Lista | P20: imagenes/MOT-EDGE70F-12-256.jpg
A21: SAM-A37-6-128 | B21: Samsung Galaxy A37 5G 6GB+128GB | C21: Celulares y tablets | D21: Celulares | E21: Samsung | F21: Morado, Negro | G21: Sin control | H21: 837000 | I21: =INDEX(Márgenes!$C$7:$C$23,MATCH(D21,Márgenes!$B$7:$B$23,0)) | J21: =MAX(H21*(1+I21),H21+Márgenes!$B$4) | K21: =IF(J21<1000000,CEILING(J21,1000),CEILING(J21,10000))-100 | L21: =K21-H21 | M21: =IF(K21=0,0,L21/K21) | O21: Lista | P21: imagenes/SAM-A37-6-128.jpg
A22: SAM-A37-8-256 | B22: Samsung Galaxy A37 5G 8GB+256GB | C22: Celulares y tablets | D22: Celulares | E22: Samsung | F22: Negro | G22: Sin control | H22: 1025000 | I22: =INDEX(Márgenes!$C$7:$C$23,MATCH(D22,Márgenes!$B$7:$B$23,0)) | J22: =MAX(H22*(1+I22),H22+Márgenes!$B$4) | K22: =IF(J22<1000000,CEILING(J22,1000),CEILING(J22,10000))-100 | L22: =K22-H22 | M22: =IF(K22=0,0,L22/K22) | O22: Lista | P22: imagenes/SAM-A37-8-256.jpg
A23: XIA-REDMI15-8-256 | B23: Xiaomi Redmi 15 8GB+256GB | C23: Celulares y tablets | D23: Celulares | E23: Xiaomi | F23: Blanco | G23: Sin control | H23: 590000 | I23: =INDEX(Márgenes!$C$7:$C$23,MATCH(D23,Márgenes!$B$7:$B$23,0)) | J23: =MAX(H23*(1+I23),H23+Márgenes!$B$4) | K23: =IF(J23<1000000,CEILING(J23,1000),CEILING(J23,10000))-100 | L23: =K23-H23 | M23: =IF(K23=0,0,L23/K23) | O23: Lista | P23: imagenes/XIA-REDMI15-8-256.jpg
A24: XIA-REDMI17-4-128 | B24: Xiaomi Redmi 17 4GB+128GB | C24: Celulares y tablets | D24: Celulares | E24: Xiaomi | F24: Negro | G24: Sin control | H24: 480000 | I24: =INDEX(Márgenes!$C$7:$C$23,MATCH(D24,Márgenes!$B$7:$B$23,0)) | J24: =MAX(H24*(1+I24),H24+Márgenes!$B$4) | K24: =IF(J24<1000000,CEILING(J24,1000),CEILING(J24,10000))-100 | L24: =K24-H24 | M24: =IF(K24=0,0,L24/K24) | O24: Lista | P24: imagenes/XIA-REDMI17-4-128.jpg
A25: XIA-REDMI17-4-256 | B25: Xiaomi Redmi 17 4GB+256GB | C25: Celulares y tablets | D25: Celulares | E25: Xiaomi | F25: Negro, Azul | G25: Sin control | H25: 570000 | I25: =INDEX(Márgenes!$C$7:$C$23,MATCH(D25,Márgenes!$B$7:$B$23,0)) | J25: =MAX(H25*(1+I25),H25+Márgenes!$B$4) | K25: =IF(J25<1000000,CEILING(J25,1000),CEILING(J25,10000))-100 | L25: =K25-H25 | M25: =IF(K25=0,0,L25/K25) | O25: Lista | P25: imagenes/XIA-REDMI17-4-256.jpg
A26: XIA-RN17-4G-4-128 | B26: Xiaomi Redmi Note 17 4G 4GB+128GB | C26: Celulares y tablets | D26: Celulares | E26: Xiaomi | F26: Negro | G26: Sin control | H26: 600000 | I26: =INDEX(Márgenes!$C$7:$C$23,MATCH(D26,Márgenes!$B$7:$B$23,0)) | J26: =MAX(H26*(1+I26),H26+Márgenes!$B$4) | K26: =IF(J26<1000000,CEILING(J26,1000),CEILING(J26,10000))-100 | L26: =K26-H26 | M26: =IF(K26=0,0,L26/K26) | O26: Lista | P26: imagenes/XIA-RN17-4G-4-128.jpg
A27: XIA-RN17-4G-6-256 | B27: Xiaomi Redmi Note 17 4G 6GB+256GB | C27: Celulares y tablets | D27: Celulares | E27: Xiaomi | F27: Negro | G27: Sin control | H27: 695000 | I27: =INDEX(Márgenes!$C$7:$C$23,MATCH(D27,Márgenes!$B$7:$B$23,0)) | J27: =MAX(H27*(1+I27),H27+Márgenes!$B$4) | K27: =IF(J27<1000000,CEILING(J27,1000),CEILING(J27,10000))-100 | L27: =K27-H27 | M27: =IF(K27=0,0,L27/K27) | O27: Lista | P27: imagenes/XIA-RN17-4G-6-256.jpg
A28: 55S6C | B28: Televisor TCL 55" LED 4K UHD Google TV | C28: TV y consolas | D28: Televisores | E28: TCL | G28: Sin control | H28: 1469902 | I28: =INDEX(Márgenes!$C$7:$C$23,MATCH(D28,Márgenes!$B$7:$B$23,0)) | J28: =MAX(H28*(1+I28),H28+Márgenes!$B$4) | K28: =IF(J28<1000000,CEILING(J28,1000),CEILING(J28,10000))-100 | L28: =K28-H28 | M28: =IF(K28=0,0,L28/K28) | O28: Lista | P28: imagenes/55S6C.jpg
A29: 65V6C | B29: Televisor TCL 65" LED 4K UHD Google TV | C29: TV y consolas | D29: Televisores | E29: TCL | G29: Sin control | H29: 2050000 | I29: =INDEX(Márgenes!$C$7:$C$23,MATCH(D29,Márgenes!$B$7:$B$23,0)) | J29: =MAX(H29*(1+I29),H29+Márgenes!$B$4) | K29: =IF(J29<1000000,CEILING(J29,1000),CEILING(J29,10000))-100 | L29: =K29-H29 | M29: =IF(K29=0,0,L29/K29) | O29: Lista | P29: imagenes/65V6C.jpg
A30: UN50U8000FPXPA | B30: Televisor Samsung 50" Crystal UHD 4K U8000F | C30: TV y consolas | D30: Televisores | E30: Samsung | G30: Sin control | H30: 1299900 | I30: =INDEX(Márgenes!$C$7:$C$23,MATCH(D30,Márgenes!$B$7:$B$23,0)) | J30: =MAX(H30*(1+I30),H30+Márgenes!$B$4) | K30: =IF(J30<1000000,CEILING(J30,1000),CEILING(J30,10000))-100 | L30: =K30-H30 | M30: =IF(K30=0,0,L30/K30) | O30: Lista | P30: imagenes/UN50U8000FPXPA.jpg
A31: UN50U8000HPXPA | B31: Televisor Samsung 50" Crystal UHD 4K U8000H | C31: TV y consolas | D31: Televisores | E31: Samsung | G31: Sin control | H31: 1399900 | I31: =INDEX(Márgenes!$C$7:$C$23,MATCH(D31,Márgenes!$B$7:$B$23,0)) | J31: =MAX(H31*(1+I31),H31+Márgenes!$B$4) | K31: =IF(J31<1000000,CEILING(J31,1000),CEILING(J31,10000))-100 | L31: =K31-H31 | M31: =IF(K31=0,0,L31/K31) | O31: Lista | P31: imagenes/UN50U8000HPXPA.jpg
A32: UN65U8000HPXPA | B32: Televisor Samsung 65" Crystal UHD 4K U8000H | C32: TV y consolas | D32: Televisores | E32: Samsung | G32: Sin control | H32: 1999900 | I32: =INDEX(Márgenes!$C$7:$C$23,MATCH(D32,Márgenes!$B$7:$B$23,0)) | J32: =MAX(H32*(1+I32),H32+Márgenes!$B$4) | K32: =IF(J32<1000000,CEILING(J32,1000),CEILING(J32,10000))-100 | L32: =K32-H32 | M32: =IF(K32=0,0,L32/K32) | O32: Lista | P32: imagenes/UN65U8000HPXPA.jpg
A33: 82XQ00EBUS | B33: Lenovo IdeaPad Slim 3 15.6" Ryzen 5 7520U | C33: Computación | D33: Portátiles | E33: Lenovo | G33: 3 | H33: 1448405 | I33: =INDEX(Márgenes!$C$7:$C$23,MATCH(D33,Márgenes!$B$7:$B$23,0)) | J33: =MAX(H33*(1+I33),H33+Márgenes!$B$4) | K33: =IF(J33<1000000,CEILING(J33,1000),CEILING(J33,10000))-100 | L33: =K33-H33 | M33: =IF(K33=0,0,L33/K33) | O33: Lista | P33: imagenes/82XQ00EBUS.jpg
A34: 82XB00BMUS | B34: Lenovo IdeaPad Slim 3i 15.6" Core i3 N305 | C34: Computación | D34: Portátiles | E34: Lenovo | G34: 3 | H34: 1357809 | I34: =INDEX(Márgenes!$C$7:$C$23,MATCH(D34,Márgenes!$B$7:$B$23,0)) | J34: =MAX(H34*(1+I34),H34+Márgenes!$B$4) | K34: =IF(J34<1000000,CEILING(J34,1000),CEILING(J34,10000))-100 | L34: =K34-H34 | M34: =IF(K34=0,0,L34/K34) | O34: Lista | P34: imagenes/82XB00BMUS.jpg
A35: 83J1002KUS | B35: Lenovo IdeaPad Slim 5i 16" Táctil Core 7 240H | C35: Computación | D35: Portátiles | E35: Lenovo | G35: 1 | H35: 2677758 | I35: =INDEX(Márgenes!$C$7:$C$23,MATCH(D35,Márgenes!$B$7:$B$23,0)) | J35: =MAX(H35*(1+I35),H35+Márgenes!$B$4) | K35: =IF(J35<1000000,CEILING(J35,1000),CEILING(J35,10000))-100 | L35: =K35-H35 | M35: =IF(K35=0,0,L35/K35) | O35: Lista | P35: imagenes/83J1002KUS.jpg
A36: 83A100PBUS | B36: Lenovo 15.6" Core i3-1315U | C36: Computación | D36: Portátiles | E36: Lenovo | G36: 10 | H36: 1533239 | I36: =INDEX(Márgenes!$C$7:$C$23,MATCH(D36,Márgenes!$B$7:$B$23,0)) | J36: =MAX(H36*(1+I36),H36+Márgenes!$B$4) | K36: =IF(J36<1000000,CEILING(J36,1000),CEILING(J36,10000))-100 | L36: =K36-H36 | M36: =IF(K36=0,0,L36/K36) | O36: Lista | P36: imagenes/83A100PBUS.jpg
A37: 16-BU0305DX | B37: HP OmniBook 3 16" Táctil Core Ultra 5 225U | C37: Computación | D37: Portátiles | E37: HP | G37: 5 | H37: 1866191 | I37: =INDEX(Márgenes!$C$7:$C$23,MATCH(D37,Márgenes!$B$7:$B$23,0)) | J37: =MAX(H37*(1+I37),H37+Márgenes!$B$4) | K37: =IF(J37<1000000,CEILING(J37,1000),CEILING(J37,10000))-100 | L37: =K37-H37 | M37: =IF(K37=0,0,L37/K37) | O37: Lista | P37: imagenes/16-BU0305DX.jpg
A38: 15-FD0127DX | B38: HP 15.6" Táctil FHD Core 7 150U | C38: Computación | D38: Portátiles | E38: HP | G38: 3 | H38: 2332429 | I38: =INDEX(Márgenes!$C$7:$C$23,MATCH(D38,Márgenes!$B$7:$B$23,0)) | J38: =MAX(H38*(1+I38),H38+Márgenes!$B$4) | K38: =IF(J38<1000000,CEILING(J38,1000),CEILING(J38,10000))-100 | L38: =K38-H38 | M38: =IF(K38=0,0,L38/K38) | O38: Lista | P38: imagenes/15-FD0127DX.jpg
A39: 14-DQ6101DX | B39: HP 14" HD Intel N150 | C39: Computación | D39: Portátiles | E39: HP | G39: 10 | H39: 826083 | I39: =INDEX(Márgenes!$C$7:$C$23,MATCH(D39,Márgenes!$B$7:$B$23,0)) | J39: =MAX(H39*(1+I39),H39+Márgenes!$B$4) | K39: =IF(J39<1000000,CEILING(J39,1000),CEILING(J39,10000))-100 | L39: =K39-H39 | M39: =IF(K39=0,0,L39/K39) | O39: Lista | P39: imagenes/14-DQ6101DX.jpg
A40: LDC15250-5434BLK-PUS | B40: Dell Inspiron 15 Táctil FHD Core i5-1334U | C40: Computación | D40: Portátiles | E40: Dell | G40: 6 | H40: 1769417 | I40: =INDEX(Márgenes!$C$7:$C$23,MATCH(D40,Márgenes!$B$7:$B$23,0)) | J40: =MAX(H40*(1+I40),H40+Márgenes!$B$4) | K40: =IF(J40<1000000,CEILING(J40,1000),CEILING(J40,10000))-100 | L40: =K40-H40 | M40: =IF(K40=0,0,L40/K40) | O40: Lista | P40: imagenes/LDC15250-5434BLK-PUS.jpg
...

Sheet Márgenes
A1: Márgenes por subcategoría
A2: Edita las celdas amarillas: los precios de la hoja Productos se recalculan solos.
A4: Ganancia mínima por unidad (COP) | B4: 12000
A6: Categoría | B6: Subcategoría | C6: Margen sobre costo | D6: Productos
A7: Accesorios | B7: Cables | C7: 1 | D7: =COUNTIF(Productos!$D:$D,B7)
A8: Accesorios | B8: Cargadores | C8: 0.8 | D8: =COUNTIF(Productos!$D:$D,B8)
A9: Accesorios | B9: Power banks | C9: 0.6 | D9: =COUNTIF(Productos!$D:$D,B9)
A10: Audio | B10: Audífonos | C10: 0.35 | D10: =COUNTIF(Productos!$D:$D,B10)
A11: Audio | B11: Parlantes | C11: 0.3 | D11: =COUNTIF(Productos!$D:$D,B11)
A12: Celulares y tablets | B12: Celulares | C12: 0.15 | D12: =COUNTIF(Productos!$D:$D,B12)
A13: Celulares y tablets | B13: Relojes inteligentes | C13: 0.3 | D13: =COUNTIF(Productos!$D:$D,B13)
A14: Celulares y tablets | B14: Tablets | C14: 0.18 | D14: =COUNTIF(Productos!$D:$D,B14)
A15: Computación | B15: Impresoras | C15: 0.15 | D15: =COUNTIF(Productos!$D:$D,B15)
A16: Computación | B16: Periféricos | C16: 0.8 | D16: =COUNTIF(Productos!$D:$D,B16)
A17: Computación | B17: Portátiles | C17: 0.12 | D17: =COUNTIF(Productos!$D:$D,B17)
A18: Hogar | B18: Cámaras de seguridad | C18: 0.35 | D18: =COUNTIF(Productos!$D:$D,B18)
... A23: TV y consolas | B23: Televisores | C23: 0.12 | D23: =COUNTIF(Productos!$D:$D,B23)

Sheet Notas
A1: Cómo se calcula el precio
A2: Precio sin redondear = el mayor entre: costo × (1 + margen de la subcategoría) y costo + ganancia mínima.
A3: Precio de venta = se redondea hacia arriba y termina en 900 (al millar por debajo de $1.000.000; a la decena de mil por encima).
A5: De dónde salen los datos
A6: Costo proveedor: "Precio de Venta" del archivo Catalogo_Dropshipping.xlsx (lista del proveedor, sin modificar), según indicó el usuario.
A7: Márgenes y ganancia mínima: propuesta inicial de Zeltron; ajústalos en la hoja Márgenes.
A8: Colores y unidades: extraídos de la descripción original. Productos con más de un color se crean como producto variable (un precio, varios colores).
A9: Categorías: las 14 del archivo se agruparon en 7 categorías con subcategorías para el menú de la tienda.
A11: Importante
A12: El archivo catalogo-woocommerce.csv ya trae los precios con los márgenes de esta versión.
A13: Si cambias márgenes aquí, pide regenerar el CSV, o ajusta el precio directamente en WooCommerce.
A14: No se crearon precios "antes" ni descuentos: la tienda solo muestra ofertas reales que cargues en "Precio rebajado".
... A19: Para subirlas a la tienda: arrastra la carpeta de imágenes a WordPress → Medios → Añadir nuevo, y luego importa catalogo-imagenes-woocommerce.csv con «Actualizar productos existentes» activado.
